Workbook
Name d.conn: Database!$S1
Name d.id: Database!#REF!
Name ff_calculation: WORKDAY(INDEX(Database!$AI:$AI,#REF!),(#REF!+#REF!))
Name fs_calculation: WORKDAY(INDEX(Database!$AI:$AI,#REF!),1+#REF!+IF(#REF! = "M",#REF!, 0))
Name ind.end: Database!#REF!
Name ind.start: Database!$R1
Name MDDataBase: BaseDeDatos[]
Name MDDataBase: BaseDeDatos[]
Name plan_end_calculation: IF(#REF!="M", WORKDAY(#REF!,(#REF!)-1), IF(#REF!="SS", IF(#REF!="SS", WORKDAY(#REF!,(#REF!+#REF!)-1), WORKDAY(INDEX(Database!$AH:$AH,#REF!),(#REF!+#REF!))), WORKDAY(#REF!,(#REF!+#REF!)-1)))
Name plan_start_calculation: IF(#REF!="M", WORKDAY(#REF!,(-1)*#REF!+1), IF(#REF!="SF", WORKDAY(#REF!,(-1)*(#REF!+#REF!)+1), IF(#REF!="FF",WORKDAY(#REF!,(-1)*(#REF!+#REF!)+1), WORKDAY(#REF!,(-1)*#REF!+1))))
Name SegmentaciónDeDatos_Project_No: #N/A
Name SegmentaciónDeDatos_Project_No1: #N/A
Name SegmentaciónDeDatos_Responsible: #N/A
Name SegmentaciónDeDatos_Responsible1: #N/A
Name SegmentaciónDeDatos_STATUS: #N/A
Name sf_calculation: WORKDAY(INDEX(Database!$AH:$AH,#REF!),(-1)+(#REF!+#REF!))
Name ss_calculation: IF(#REF!="M", WORKDAY(INDEX(Database!$AH:$AH,#REF!),(#REF!+#REF!)), WORKDAY(INDEX(Database!$AH:$AH,#REF!),#REF!))
Name type: #REF!

Sheet HD Forecast 2025
A1: #VALUE! | B1: Month | C1: September | Z1: October | BE1: November | CI1: December
B2: Week | C2: 37 | J2: 38 | Q2: 39 | X2: 40 | AE2: 41 | AL2: 42 | AS2: 43 | AZ2: 44 | BG2: 45 | BN2: 46 | BU2: 47 | CB2: 48 | CI2: 49 | CP2: 50 | CW2: 51 | DD2: 52
B3: Day | C3: 8 | D3: 9 | E3: 10 | F3: 11 | G3: 12 | H3: 13 | I3: 14 | J3: 15 | K3: 16 | L3: 17 | M3: 18 | N3: 19 | O3: 20 | P3: 21 | Q3: 22 | R3: 23 | S3: 24 | T3: 25 | U3: 26 | V3: 27 | W3: 28 | X3: 29 | Y3: 30 | Z3: 1 | AA3: 2 | AB3: 3 | AC3: 4 | AD3: 5 | AE3: 6 | AF3: 7 | AG3: 8 | AH3: 9 | AI3: 10 | AJ3: 11 | AK3: 12 | AL3: 13 | AM3: 14 | AN3: 15 | AO3: 16 | AP3: 17 | AQ3: 18 | AR3: 19 | AS3: 20 | AT3: 21 | AU3: 22 | AV3: 23 | AW3: 24 | AX3: 25 | AY3: 26 | AZ3: 27 | BA3: 28 | BB3: 29 | BC3: 30 | BD3: 31 | BE3: 1 | BF3: 2 | BG3: 3 | BH3: 4 | BI3: 5 | BJ3: 6 | BK3: 7 | BL3: 8 | BM3: 9 | BN3: 10 | BO3: 11 | BP3: 12 | BQ3: 13 | BR3: 14 | BS3: 15 | BT3: 16 | BU3: 17 | BV3: 18 | BW3: 19 | BX3: 20 | BY3: 21 | BZ3: 22 | CA3: 23 | CB3: 24 | CC3: 25 | CD3: 26 | CE3: 27 | CF3: 28 | CG3: 29 | CH3: 30 | CI3: 1 | CJ3: 2 | CK3: 3 | CL3: 4 | CM3: 5 | CN3: 6 | CO3: 7 | CP3: 8 | CQ3: 9 | CR3: 10 | CS3: 11 | CT3: 12 | CU3: 13 | CV3: 14 | CW3: 15 | CX3: 16 | CY3: 17 | CZ3: 18 | DA3: 19 | DB3: 20 | DC3: 21 | DD3: 22 | DE3: 23 | DF3: 24 | DG3: 25 | DH3: 26 | DI3: 27 | DJ3: 28 | DK3: 29 | DL3: 30 | DM3: 31
A4: IND | B4: Juan Adame | C4: 3336 | D4: 3336 | E4: 3336 | F4: 3328 | G4: 3328 | J4: 3336 | K4: PTO | L4: 3336 | M4: 3328 | N4: 3336 | Q4: 3336 | R4: 3328 | S4: 3328 | T4: PTO | U4: PTO | X4: 3328 | Y4: 3336 | Z4: 3328 | AA4: PTO | AB4: PTO | AE4: 3336 | AF4: 3328 | AG4: 3268 | AH4: ASSY | AI4: ASSY | AL4: 3300 | AM4: 3328 | AN4: 3336 | AO4: IND | AP4: IND | AS4: 3264 | AT4: IND | AU4: IND | AV4: IND | AW4: PTO | AZ4: PTO | BA4: PTO | BB4: PTO | BC4: PTO | BD4: PTO | BG4: 3336 | BH4: 3351 | BI4: 3351 | BJ4: IND | BK4: IND | BN4: 3351 | BO4: 3351 | BP4: IND | BQ4: IND | BR4: IND | BU4: PTO | BV4: 3351 | BW4: 3351 | BX4: 3351 | BY4: 3300 | CB4: 3272 | CC4: IND | CD4: IND | CE4: IND | CF4: IND | CI4: 3328 | CJ4: IND | CK4: IND | CL4: IND | CM4: IND | CP4: IND | CQ4: IND | CR4: IND | CS4: IND | CT4: IND | CW4: 3328 | CX4: IND | CY4: IND | CZ4: IND | DA4: IND | DD4: 3272 | DE4: IND | DF4: IND | DG4: PTO | DH4: PTO | DK4: PTO | DL4: PTO | DM4: PTO
A5: MNG | C5: 3336 | D5: 3336 | E5: 3336 | F5: 3328 | G5: 3328 | J5: 3336 | K5: PTO | L5: 3336 | M5: 3328 | N5: 3336 | Q5: 3336 | R5: 3328 | S5: 3328 | T5: PTO | U5: PTO | X5: 3328 | Y5: 3336 | Z5: 3328 | AA5: PTO | AB5: PTO | AE5: 3336 | AF5: 3328 | AG5: 3268 | AH5: ASSY | AI5: ASSY | AL5: 3300 | AM5: 3328 | AN5: 3336 | AO5: IND | AP5: IND | AS5: 3264 | AT5: IND | AU5: IND | AV5: IND | AW5: PTO | AZ5: PTO | BA5: PTO | BB5: PTO | BC5: PTO | BD5: PTO | BG5: 3336 | BH5: 3351 | BI5: 3351 | BJ5: IND | BK5: IND | BN5: 3351 | BO5: 3351 | BP5: IND | BQ5: IND | BR5: IND | BU5: PTO | BV5: 3351 | BW5: 3351 | BX5: 3351 | BY5: 3300 | CB5: 3300 | CC5: IND | CD5: IND | CE5: IND | CF5: IND | CI5: 3272 | CJ5: IND | CK5: IND | CL5: IND | CM5: IND | CP5: IND | CQ5: IND | CR5: IND | CS5: IND | CT5: IND | CW5: 3328 | CX5: IND | CY5: IND | CZ5: IND | DA5: IND | DD5: IND | DE5: IND | DF5: IND | DG5: PTO | DH5: PTO | DK5: PTO | DL5: PTO | DM5: PTO
A6: ASSY | C6: 3336 | D6: 3336 | E6: 3336 | F6: 3328 | G6: 3328 | J6: 3336 | K6: PTO | L6: 3336 | M6: 3328 | N6: 3300 | Q6: 3336 | R6: 3328 | S6: 3328 | T6: PTO | U6: PTO | X6: 3328 | Y6: 3336 | Z6: 3328 | AA6: PTO | AB6: PTO | AE6: 3336 | AF6: 3328 | AG6: 3264 | AH6: ASSY | AI6: ASSY | AL6: 3328 | AM6: 3328 | AN6: 3336 | AO6: IND | AP6: IND | AS6: 3268 | AT6: IND | AU6: IND | AV6: IND | AW6: PTO | AZ6: PTO | BA6: PTO | BB6: PTO | BC6: PTO | BD6: PTO | BG6: 3351 | BH6: 3351 | BI6: IND | BJ6: IND | BK6: IND | BN6: 3351 | BO6: 3351 | BP6: IND | BQ6: IND | BR6: IND | BU6: PTO | BV6: 3351 | BW6: 3351 | BX6: 3351 | BY6: 3272 | CB6: 3300 | CC6: IND | CD6: IND | CE6: IND | CF6: IND | CI6: 3336 | CJ6: IND | CK6: IND | CL6: IND | CM6: IND | CP6: IND | CQ6: IND | CR6: IND | CS6: IND | CT6: IND | CW6: 3336 | CX6: IND | CY6: IND | CZ6: IND | DA6: IND | DD6: IND | DE6: IND | DF6: IND | DG6: PTO | DH6: PTO | DK6: PTO | DL6: PTO | DM6: PTO
A7: PTO | C7: 3336 | D7: 3336 | E7: 3336 | F7: 3328 | G7: 3328 | J7: 3336 | K7: PTO | L7: 3336 | M7: 3328 | N7: 3300 | Q7: 3336 | R7: 3328 | S7: 3328 | T7: PTO | U7: PTO | X7: 3328 | Y7: 3268 | Z7: 3328 | AA7: PTO | AB7: PTO | AE7: 3336 | AF7: 3328 | AG7: 3264 | AH7: ASSY | AI7: ASSY | AL7: 3328 | AM7: 3336 | AN7: IND | AO7: IND | AP7: IND | AS7: 3328 | AT7: IND | AU7: IND | AV7: IND | AW7: PTO | AZ7: PTO | BA7: PTO | BB7: PTO | BC7: PTO | BD7: PTO | BG7: 3351 | BH7: 3351 | BI7: IND | BJ7: IND | BK7: IND | BN7: 3351 | BO7: 3351 | BP7: IND | BQ7: IND | BR7: IND | BU7: PTO | BV7: 3351 | BW7: 3351 | BX7: 3351 | BY7: IND | CB7: 3328 | CC7: IND | CD7: IND | CE7: IND | CF7: IND | CI7: 3336 | CJ7: IND | CK7: IND | CL7: IND | CM7: IND | CP7: IND | CQ7: IND | CR7: IND | CS7: IND | CT7: IND | CW7: IND | CX7: IND | CY7: IND | CZ7: IND | DA7: IND | DD7: IND | DE7: IND | DF7: IND | DG7: PTO | DH7: PTO | DK7: PTO | DL7: PTO | DM7: PTO
A8: 3268 | C8: 3336 | D8: 3336 | E8: 3336 | F8: 3328 | G8: 3328 | J8: 3336 | K8: PTO | L8: 3336 | M8: 3328 | N8: 3300 | Q8: 3336 | R8: 3328 | S8: 3328 | T8: PTO | U8: PTO | X8: 3328 | Y8: 3268 | Z8: 3328 | AA8: PTO | AB8: PTO | AE8: 3336 | AF8: IND | AG8: 3272 | AH8: ASSY | AI8: ASSY | AL8: 3328 | AM8: 3336 | AN8: IND | AO8: IND | AP8: IND | AS8: 3351 | AT8: IND | AU8: IND | AV8: IND | AW8: PTO | AZ8: PTO | BA8: PTO | BB8: PTO | BC8: PTO | BD8: PTO | BG8: 3351 | BH8: 3351 | BI8: IND | BJ8: IND | BK8: IND | BN8: 3351 | BO8: 3351 | BP8: IND | BQ8: IND | BR8: IND | BU8: PTO | BV8: 3351 | BW8: 3351 | BX8: 3351 | BY8: IND | CB8: 3328 | CC8: IND | CD8: IND | CE8: IND | CF8: IND | CI8: 3336 | CJ8: IND | CK8: IND | CL8: PTO | CM8: IND | CP8: IND | CQ8: IND | CR8: IND | CS8: IND | CT8: IND | CW8: IND | CX8: IND | CY8: IND | CZ8: IND | DA8: IND | DD8: IND | DE8: IND | DF8: IND | DG8: PTO | DH8: PTO | DK8: PTO | DL8: PTO | DM8: PTO
A9: 3335 | C9: 3336 | D9: 3336 | E9: 3336 | F9: 3328 | G9: 3328 | J9: 3336 | K9: PTO | L9: 3336 | M9: 3328 | N9: IND | Q9: 3336 | R9: 3328 | S9: 3328 | T9: PTO | U9: PTO | X9: 3328 | Y9: 3328 | Z9: IND | AA9: PTO | AB9: PTO | AE9: IND | AF9: IND | AG9: ASSY | AH9: ASSY | AI9: ASSY | AL9: 3328 | AM9: 3336 | AN9: IND | AO9: IND | AP9: IND | AS9: 3351 | AT9: IND | AU9: IND | AV9: IND | AW9: PTO | AZ9: PTO | BA9: PTO | BB9: PTO | BC9: PTO | BD9: PTO | BG9: 3351 | BH9: 3351 | BI9: IND | BJ9: IND | BK9: IND | BN9: 3351 | BO9: 3351 | BP9: IND | BQ9: IND | BR9: IND | BU9: PTO | BV9: 3351 | BW9: 3351 | BX9: 3351 | BY9: IND | CB9: 3336 | CC9: IND | CD9: IND | CE9: IND | CF9: IND | CI9: 3336 | CJ9: IND | CK9: IND | CL9: PTO | CM9: IND | CP9: IND | CQ9: IND | CR9: IND | CS9: IND | CT9: IND | CW9: IND | CX9: IND | CY9: IND | CZ9: IND | DA9: IND | DD9: IND | DE9: IND | DF9: IND | DG9: PTO | DH9: PTO | DK9: PTO | DL9: PTO | DM9: PTO
A10: 3332 | C10: 3336 | D10: 3336 | E10: 3336 | F10: 3328 | G10: 3264 | J10: 3336 | K10: PTO | L10: 3336 | M10: 3328 | N10: 3272 | Q10: 3336 | R10: 3328 | S10: 3328 | T10: PTO | U10: PTO | X10: 3328 | Y10: 3328 | Z10: IND | AA10: PTO | AB10: PTO | AE10: IND | AF10: IND | AG10: ASSY | AH10: ASSY | AI10: ASSY | AL10: 3328 | AM10: 3336 | AN10: IND | AO10: IND | AP10: IND | AS10: 3351 | AT10: IND | AU10: IND | AV10: IND | AW10: PTO | AZ10: PTO | BA10: PTO | BB10: PTO | BC10: PTO | BD10: PTO | BG10: 3351 | BH10: 3351 | BI10: IND | BJ10: IND | BK10: IND | BN10: 3351 | BO10: 3351 | BP10: IND | BQ10: IND | BR10: IND | BU10: PTO | BV10: 3351 | BW10: 3351 | BX10: 3351 | BY10: IND | CB10: IND | CC10: IND | CD10: IND | CE10: IND | CF10: IND | CI10: 3336 | CJ10: IND | CK10: IND | CL10: PTO | CM10: IND | CP10: IND | CQ10: IND | CR10: IND | CS10: IND | CT10: IND | CW10: IND | CX10: IND | CY10: IND | CZ10: IND | DA10: IND | DD10: IND | DE10: IND | DF10: IND | DG10: PTO | DH10: PTO | DK10: PTO | DL10: PTO | DM10: PTO
A11: 3328 | C11: 3336 | D11: 3336 | E11: 3268 | F11: 3328 | G11: 3264 | J11: 3336 | K11: PTO | L11: 3300 | M11: 3328 | N11: 3264 | Q11: 3336 | R11: 3328 | S11: 3328 | T11: PTO | U11: PTO | X11: 3328 | Y11: 3328 | Z11: 3264 | AA11: PTO | AB11: PTO | AE11: IND | AF11: IND | AG11: ASSY | AH11: ASSY | AI11: ASSY | AL11: 3328 | AM11: 3336 | AN11: IND | AO11: IND | AP11: IND | AS11: 3351 | AT11: IND | AU11: IND | AV11: IND | AW11: PTO | AZ11: PTO | BA11: PTO | BB11: PTO | BC11: PTO | BD11: PTO | BG11: 3351 | BH11: 3351 | BI11: IND | BJ11: IND | BK11: IND | BN11: 3351 | BO11: 3351 | BP11: IND | BQ11: IND | BR11: IND | BU11: PTO | BV11: 3351 | BW11: 3351 | BX11: 3351 | BY11: IND | CB11: IND | CC11: IND | CD11: IND | CE11: IND | CF11: IND | CI11: 3336 | CJ11: IND | CK11: IND | CL11: PTO | CM11: IND | CP11: IND | CQ11: IND | CR11: IND | CS11: IND | CT11: IND | CW11: IND | CX11: IND | CY11: IND | CZ11: IND | DA11: IND | DD11: IND | DE11: IND | DF11: IND | DG11: PTO | DH11: PTO | DK11: PTO | DL11: PTO | DM11: PTO
A12: 3346 | C12: 3336 | D12: 3336 | E12: 3268 | F12: 3328 | G12: 3272 | J12: 3336 | K12: PTO | L12: 3300 | M12: 3328 | N12: 3264 | Q12: 3328 | R12: 3272 | S12: 3328 | T12: PTO | U12: PTO | X12: 3328 | Y12: 3328 | Z12: 3264 | AA12: PTO | AB12: PTO | AE12: IND | AF12: IND | AG12: ASSY | AH12: ASSY | AI12: ASSY | AL12: 3328 | AM12: 3336 | AN12: IND | AO12: IND | AP12: IND | AS12: 3351 | AT12: IND | AU12: IND | AV12: IND | AW12: PTO | AZ12: PTO | BA12: PTO | BB12: PTO | BC12: PTO | BD12: PTO | BG12: 3351 | BH12: 3351 | BI12: IND | BJ12: IND | BK12: IND | BN12: 3351 | BO12: 3351 | BP12: IND | BQ12: IND | BR12: IND | BU12: PTO | BV12: 3351 | BW12: 3351 | BX12: 3351 | BY12: IND | CB12: IND | CC12: IND | CD12: IND | CE12: IND | CF12: IND | CI12: IND | CJ12: IND | CK12: IND | CL12: PTO | CM12: IND | CP12: IND | CQ12: IND | CR12: IND | CS12: IND | CT12: IND | CW12: IND | CX12: IND | CY12: IND | CZ12: IND | DA12: IND | DD12: IND | DE12: IND | DF12: IND | DG12: PTO | DH12: PTO | DK12: PTO | DL12: PTO | DM12: PTO
A13: 3334
A14: 3336
A15: 3272
A16: 3340 | B16: Fidel Maldonado | C16: 3332 | D16: 3332 | E16: IND | F16: 3328 | G16: 3328 | J16: PTO | K16: PTO | L16: 3328 | M16: 3332 | N16: 3335 | Q16: 3328 | R16: 3332 | S16: 3335 | T16: IND | U16: IND | X16: 3328 | Y16: ASSY | Z16: ASSY | AA16: ASSY | AB16: ASSY | AE16: ASSY | AF16: ASSY | AG16: ASSY | AH16: ASSY | AI16: ASSY | AL16: ASSY | AM16: ASSY | AN16: IND | AO16: IND | AP16: IND | AS16: 3328 | AT16: IND | AU16: IND | AV16: IND | AW16: IND | AZ16: IND | BA16: IND | BB16: IND | BC16: IND | BD16: PTO | BG16: PTO | BH16: IND | BI16: IND | BJ16: IND | BK16: IND | BN16: IND | BO16: IND | BP16: IND | BQ16: IND | BR16: IND | BU16: PTO | BV16: IND | BW16: IND | BX16: IND | BY16: IND | CB16: 3321 | CC16: 3321 | CD16: IND | CE16: IND | CF16: 3335 | CI16: 3321 | CJ16: 3328 | CK16: IND | CL16: IND | CM16: IND | CP16: IND | CQ16: IND | CR16: IND | CS16: IND | CT16: IND | CW16: 3335 | CX16: IND | CY16: IND | CZ16: IND | DA16: IND | DD16: 3332 | DE16: 3332 | DF16: 3335 | DG16: PTO | DH16: PTO | DK16: PTO | DL16: PTO | DM16: PTO
A17: 3300 | C17: 3332 | D17: 3332 | E17: IND | F17: 3328 | G17: 3328 | J17: PTO | K17: PTO | L17: 3328 | M17: 3332 | N17: IND | Q17: 3328 | R17: 3332 | S17: 3335 | T17: IND | U17: IND | X17: 3328 | Y17: ASSY | Z17: ASSY | AA17: ASSY | AB17: ASSY | AE17: ASSY | AF17: ASSY | AG17: ASSY | AH17: ASSY | AI17: ASSY | AL17: ASSY | AM17: ASSY | AN17: IND | AO17: IND | AP17: IND | AS17: IND | AT17: IND | AU17: IND | AV17: IND | AW17: IND | AZ17: IND | BA17: IND | BB17: IND | BC17: IND | BD17: PTO | BG17: PTO | BH17: IND | BI17: IND | BJ17: IND | BK17: IND | BN17: IND | BO17: IND | BP17: IND | BQ17: IND | BR17: IND | BU17: PTO | BV17: IND | BW17: IND | BX17: IND | BY17: IND | CB17: 3321 | CC17: 3321 | CD17: IND | CE17: IND | CF17: 3335 | CI17: 3321 | CJ17: 3334 | CK17: IND | CL17: IND | CM17: IND | CP17: IND | CQ17: IND | CR17: IND | CS17: IND | CT17: IND | CW17: IND | CX17: IND | CY17: IND | CZ17: IND | DA17: IND | DD17: 3332 | DE17: 3332 | DF17: 3335 | DG17: PTO | DH17: PTO | DK17: PTO | DL17: PTO | DM17: PTO
A18: 3331 | C18: 3332 | D18: 3332 | E18: IND | F18: 3328 | G18: 3328 | J18: PTO | K18: PTO | L18: 3328 | M18: 3332 | N18: IND | Q18: 3328 | R18: 3332 | S18: 3335 | T18: IND | U18: IND | X18: 3336 | Y18: ASSY | Z18: ASSY | AA18: ASSY | AB18: ASSY | AE18: ASSY | AF18: ASSY | AG18: ASSY | AH18: ASSY | AI18: ASSY | AL18: ASSY | AM18: ASSY | AN18: IND | AO18: IND | AP18: IND | AS18: IND | AT18: IND | AU18: IND | AV18: IND | AW18: IND | AZ18: IND | BA18: IND | BB18: IND | BC18: IND | BD18: PTO | BG18: PTO | BH18: IND | BI18: IND | BJ18: IND | BK18: IND | BN18: IND | BO18: IND | BP18: IND | BQ18: IND | BR18: IND | BU18: PTO | BV18: IND | BW18: IND | BX18: IND | BY18: IND | CB18: 3321 | CC18: 3321 | CD18: IND | CE18: IND | CF18: IND | CI18: 3321 | CJ18: 3334 | CK18: IND | CL18: IND | CM18: IND | CP18: IND | CQ18: IND | CR18: IND | CS18: IND | CT18: IND | CW18: IND | CX18: IND | CY18: IND | CZ18: IND | DA18: IND | DD18: 3332 | DE18: 3332 | DF18: 3334 | DG18: PTO | DH18: PTO | DK18: PTO | DL18: PTO | DM18: PTO
A19: 3341 | C19: 3332 | D19: 3332 | E19: IND | F19: 3328 | G19: 3328 | J19: PTO | K19: PTO | L19: 3328 | M19: 3332 | N19: IND | Q19: 3328 | R19: 3332 | S19: 3335 | T19: IND | U19: IND | X19: 3336 | Y19: ASSY | Z19: ASSY | AA19: ASSY | AB19: ASSY | AE19: ASSY | AF19: ASSY | AG19: ASSY | AH19: ASSY | AI19: ASSY | AL19: ASSY | AM19: ASSY | AN19: IND | AO19: IND | AP19: IND | AS19: IND | AT19: IND | AU19: IND | AV19: IND | AW19: IND | AZ19: IND | BA19: IND | BB19: IND | BC19: IND | BD19: PTO | BG19: PTO | BH19: IND | BI19: IND | BJ19: IND | BK19: IND | BN19: IND | BO19: IND | BP19: IND | BQ19: IND | BR19: IND | BU19: PTO | BV19: IND | BW19: IND | BX19: IND | BY19: IND | CB19: 3321 | CC19: 3321 | CD19: IND | CE19: IND | CF19: IND | CI19: 3321 | CJ19: 3335 | CK19: IND | CL19: IND | CM19: IND | CP19: IND | CQ19: IND | CR19: IND | CS19: IND | CT19: IND | CW19: IND | CX19: IND | CY19: IND | CZ19: IND | DA19: IND | DD19: 3332 | DE19: 3332 | DF19: IND | DG19: PTO | DH19: PTO | DK19: PTO | DL19: PTO | DM19: PTO
A20: 3351 | C20: 3332 | D20: 3332 | E20: IND | F20: 3328 | G20: 3328 | J20: PTO | K20: PTO | L20: 3328 | M20: 3332 | N20: IND | Q20: IND | R20: 3332 | S20: 3335 | T20: IND | U20: IND | X20: 3334 | Y20: ASSY | Z20: ASSY | AA20: ASSY | AB20: ASSY | AE20: ASSY | AF20: ASSY | AG20: ASSY | AH20: ASSY | AI20: ASSY | AL20: ASSY | AM20: ASSY | AN20: IND | AO20: IND | AP20: IND | AS20: IND | AT20: IND | AU20: IND | AV20: IND | AW20: IND | AZ20: IND | BA20: IND | BB20: IND | BC20: IND | BD20: PTO | BG20: PTO | BH20: IND | BI20: IND | BJ20: IND | BK20: IND | BN20: IND | BO20: IND | BP20: IND | BQ20: IND | BR20: IND | BU20: PTO | BV20: IND | BW20: IND | BX20: IND | BY20: IND | CB20: 3321 | CC20: 3321 | CD20: IND | CE20: IND | CF20: IND | CI20: 3321 | CJ20: 3335 | CK20: IND | CL20: PTO | CM20: IND | CP20: IND | CQ20: IND | CR20: IND | CS20: IND | CT20: IND | CW20: IND | CX20: IND | CY20: IND | CZ20: IND | DA20: IND | DD20: 3332 | DE20: 3332 | DF20: IND | DG20: PTO | DH20: PTO | DK20: PTO | DL20: PTO | DM20: PTO
A21: 3321 | C21: 3332 | D21: 3332 | E21: IND | F21: 3328 | G21: 3328 | J21: PTO | K21: PTO | L21: 3328 | M21: 3332 | N21: IND | Q21: IND | R21: 3332 | S21: 3335 | T21: IND | U21: IND | X21: 3334 | Y21: ASSY | Z21: ASSY | AA21: ASSY | AB21: ASSY | AE21: ASSY | AF21: ASSY | AG21: ASSY | AH21: ASSY | AI21: ASSY | AL21: ASSY | AM21: ASSY | AN21: IND | AO21: IND | AP21: IND | AS21: IND | AT21: IND | AU21: IND | AV21: IND | AW21: IND | AZ21: IND | BA21: IND | BB21: IND | BC21: IND | BD21: PTO | BG21: PTO | BH21: IND | BI21: IND | BJ21: IND | BK21: IND | BN21: IND | BO21: IND | BP21: IND | BQ21: IND | BR21: IND | BU21: PTO | BV21: IND | BW21: IND | BX21: IND | BY21: IND | CB21: 3321 | CC21: 3321 | CD21: IND | CE21: IND | CF21: IND | CI21: 3321 | CJ21: IND | CK21: IND | CL21: PTO | CM21: IND | CP21: IND | CQ21: IND | CR21: IND | CS21: IND | CT21: IND | CW21: IND | CX21: IND | CY21: IND | CZ21: IND | DA21: IND | DD21: 3332 | DE21: 3332 | DF21: IND | DG21: PTO | DH21: PTO | DK21: PTO | DL21: PTO | DM21: PTO
C22: 3332 | D22: 3332 | E22: IND | F22: 3328 | G22: 3328 | J22: PTO | K22: PTO | L22: 3328 | M22: 3332 | N22: IND | Q22: IND | R22: 3332 | S22: IND | T22: IND | U22: IND | X22: 3334 | Y22: ASSY | Z22: ASSY | AA22: ASSY | AB22: ASSY | AE22: ASSY | AF22: ASSY | AG22: ASSY | AH22: ASSY | AI22: ASSY | AL22: ASSY | AM22: ASSY | AN22: IND | AO22: IND | AP22: IND | AS22: IND | AT22: IND | AU22: IND | AV22: IND | AW22: IND | AZ22: IND | BA22: IND | BB22: IND | BC22: IND | BD22: PTO | BG22: PTO | BH22: IND | BI22: IND | BJ22: IND | BK22: IND | BN22: IND | BO22: IND | BP22: IND | BQ22: IND | BR22: IND | BU22: PTO | BV22: IND | BW22: IND | BX22: IND | BY22: IND | CB22: 3321 | CC22: 3321 | CD22: IND | CE22: IND | CF22: IND | CI22: 3321 | CJ22: IND | CK22: IND | CL22: PTO | CM22: IND | CP22: IND | CQ22: IND | CR22: IND | CS22: IND | CT22: IND | CW22: IND | CX22: IND | CY22: IND | CZ22: IND | DA22: IND | DD22: 3332 | DE22: 3332 | DF22: IND | DG22: PTO | DH22: PTO | DK22: PTO | DL22: PTO | DM22: PTO
C23: 3332 | D23: 3332 | E23: IND | F23: 3328 | G23: 3328 | J23: PTO | K23: PTO | L23: 3328 | M23: 3332 | N23: IND | Q23: IND | R23: 3332 | S23: IND | T23: IND | U23: IND | X23: 3334 | Y23: ASSY | Z23: ASSY | AA23: ASSY | AB23: ASSY | AE23: ASSY | AF23: ASSY | AG23: ASSY | AH23: ASSY | AI23: ASSY | AL23: ASSY | AM23: ASSY | AN23: IND | AO23: IND | AP23: IND | AS23: IND | AT23: IND | AU23: IND | AV23: IND | AW23: IND | AZ23: IND | BA23: IND | BB23: IND | BC23: IND | BD23: PTO | BG23: PTO | BH23: IND | BI23: IND | BJ23: IND | BK23: IND | BN23: IND | BO23: IND | BP23: IND | BQ23: IND | BR23: IND | BU23: PTO | BV23: IND | BW23: IND | BX23: IND | BY23: IND | CB23: 3321 | CC23: 3321 | CD23: IND | CE23: IND | CF23: IND | CI23: 3321 | CJ23: IND | CK23: IND | CL23: PTO | CM23: IND | CP23: IND | CQ23: IND | CR23: IND | CS23: IND | CT23: IND | CW23: IND | CX23: IND | CY23: IND | CZ23: IND | DA23: IND | DD23: 3332 | DE23: 3332 | DF23: IND | DG23: PTO | DH23: PTO | DK23: PTO | DL23: PTO | DM23: PTO
C24: 3332 | D24: 3332 | E24: IND | F24: 3328 | G24: 3328 | J24: PTO | K24: PTO | L24: 3328 | M24: 3332 | N24: IND | Q24: IND | R24: 3332 | S24: IND | T24: IND | U24: IND | X24: ASSY | Y24: ASSY | Z24: ASSY | AA24: ASSY | AB24: ASSY | AE24: ASSY | AF24: ASSY | AG24: ASSY | AH24: ASSY | AI24: ASSY | AL24: ASSY | AM24: ASSY | AN24: IND | AO24: IND | AP24: IND | AS24: IND | AT24: IND | AU24: IND | AV24: IND | AW24: IND | AZ24: IND | BA24: IND | BB24: IND | BC24: IND | BD24: PTO | BG24: PTO | BH24: IND | BI24: IND | BJ24: IND | BK24: IND | BN24: IND | BO24: IND | BP24: IND | BQ24: IND | BR24: IND | BU24: PTO | BV24: IND | BW24: IND | BX24: IND | BY24: IND | CB24: 3321 | CC24: 3321 | CD24: IND | CE24: IND | CF24: IND | CI24: 3321 | CJ24: IND | CK24: IND | CL24: PTO | CM24: IND | CP24: IND | CQ24: IND | CR24: IND | CS24: IND | CT24: IND | CW24: IND | CX24: IND | CY24: IND | CZ24: IND | DA24: IND | DD24: 3332 | DE24: 3332 | DF24: IND | DG24: PTO | DH24: PTO | DK24: PTO | DL24: PTO | DM24: PTO
B28: Hilda Mata | C28: 3336 | D28: 3336 | E28: 3336 | F28: 3346 | G28: 3328 | J28: 3336 | K28: PTO | L28: 3336 | M28: 3346 | N28: 3328 | Q28: PTO | R28: 3328 | S28: 3328 | T28: 3336 | U28: 3346 | X28: PTO | Y28: 3328 | Z28: 3328 | AA28: 3336 | AB28: IND | AE28: PTO | AF28: 3336 | AG28: 3272 | AH28: ASSY | AI28: ASSY | AL28: 3272 | AM28: 3328 | AN28: 3328 | AO28: 3346 | AP28: 3346 | AS28: 3346 | AT28: 3346 | AU28: 3346 | AV28: IND | AW28: IND | AZ28: 3328 | BA28: IND | BB28: IND | BC28: IND | BD28: IND | BG28: 3346 | BH28: 3346 | BI28: IND | BJ28: IND | BK28: IND | BN28: 3346 | BO28: 3346 | BP28: IND | BQ28: IND | BR28: PTO | BU28: PTO | BV28: 3328 | BW28: IND | BX28: IND | BY28: IND | CB28: 3346 | CC28: IND | CD28: IND | CE28: IND | CF28: IND | CI28: 3328 | CJ28: IND | CK28: IND | CL28: IND | CM28: IND | CP28: 3346 | CQ28: IND | CR28: IND | CS28: IND | CT28: PTO | CW28: 3336 | CX28: IND | CY28: IND | CZ28: IND | DA28: IND | DD28: 3346 | DE28: IND | DF28: IND | DG28: PTO | DH28: IND | DK28: IND | DL28: IND | DM28: IND
C29: 3336 | D29: 3336 | E29: 3336 | F29: 3346 | G29: 3328 | J29: 3336 | K29: PTO | L29: 3336 | M29: 3346 | N29: 3328 | Q29: PTO | R29: 3328 | S29: 3328 | T29: 3336 | U29: 3346 | X29: PTO | Y29: 3328 | Z29: 3328 | AA29: 3336 | AB29: IND | AE29: PTO | AF29: 3336 | AG29: ASSY | AH29: ASSY | AI29: ASSY | AL29: 3272 | AM29: 3328 | AN29: 3328 | AO29: 3346 | AP29: 3346 | AS29: 3346 | AT29: 3346 | AU29: 3346 | AV29: IND | AW29: IND | AZ29: 3336 | BA29: IND | BB29: IND | BC29: IND | BD29: IND | BG29: 3346 | BH29: 3328 | BI29: IND | BJ29: IND | BK29: IND | BN29: 3346 | BO29: 3346 | BP29: IND | BQ29: IND | BR29: PTO | BU29: PTO | BV29: 3336 | BW29: IND | BX29: IND | BY29: IND | CB29: 3346 | CC29: IND | CD29: IND | CE29: IND | CF29: IND | CI29: 3336 | CJ29: IND | CK29: IND | CL29: IND | CM29: IND | CP29: 3346 | CQ29: IND | CR29: IND | CS29: IND | CT29: PTO | CW29: 3335 | CX29: IND | CY29: IND | CZ29: IND | DA29: IND | DD29: 3346 | DE29: IND | DF29: IND | DG29: PTO | DH29: IND | DK29: IND | DL29: IND | DM29: IND
C30: 3336 | D30: 3336 | E30: 3346 | F30: 3346 | G30: 3328 | J30: 3336 | K30: PTO | L30: 3336 | M30: 3346 | N30: 3328 | Q30: PTO | R30: 3328 | S30: 3328 | T30: 3336 | U30: IND | X30: PTO | Y30: 3328 | Z30: 3328 | AA30: 3336 | AB30: IND | AE30: PTO | AF30: 3336 | AG30: ASSY | AH30: ASSY | AI30: ASSY | AL30: 3272 | AM30: 3328 | AN30: 3336 | AO30: 3346 | AP30: 3346 | AS30: 3346 | AT30: 3346 | AU30: 3328 | AV30: IND | AW30: IND | AZ30: IND | BA30: IND | BB30: IND | BC30: IND | BD30: IND | BG30: 3346 | BH30: IND | BI30: IND | BJ30: IND | BK30: IND | BN30: 3346 | BO30: 3346 | BP30: IND | BQ30: IND | BR30: PTO | BU30: PTO | BV30: 3346 | BW30: IND | BX30: IND | BY30: IND | CB30: 3328 | CC30: IND | CD30: IND | CE30: IND | CF30: IND | CI30: 3336 | CJ30: IND | CK30: IND | CL30: IND | CM30: IND | CP30: 3346 | CQ30: IND | CR30: IND | CS30: IND | CT30: PTO | CW30: 3346 | CX30: IND | CY30: IND | CZ30: IND | DA30: IND | DD30: IND | DE30: IND | DF30: IND | DG30: PTO | DH30: IND | DK30: IND | DL30: IND | DM30: IND
C31: 3336 | D31: 3336 | E31: 3346 | F31: 3346 | G31: 3328 | J31: 3336 | K31: PTO | L31: 3336 | M31: 3346 | N31: 3328 | Q31: PTO | R31: 3328 | S31: 3328 | T31: 3336 | U31: IND | X31: PTO | Y31: 3328 | Z31: 3328 | AA31: IND | AB31: IND | AE31: PTO | AF31: 3336 | AG31: ASSY | AH31: ASSY | AI31: ASSY | AL31: 3272 | AM31: 3328 | AN31: 3336 | AO31: 3346 | AP31: 3346 | AS31: 3346 | AT31: 3346 | AU31: 3336 | AV31: IND | AW31: IND | AZ31: IND | BA31: IND | BB31: IND | BC31: IND | BD31: IND | BG31: 3346 | BH31: IND | BI31: IND | BJ31: IND | BK31: IND | BN31: 3346 | BO31: 3346 | BP31: IND | BQ31: IND | BR31: PTO | BU31: PTO | BV31: 3346 | BW31: IND | BX31: IND | BY31: IND | CB31: IND | CC31: IND | CD31: IND | CE31: IND | CF31: IND | CI31: 3336 | CJ31: IND | CK31: IND | CL31: IND | CM31: IND | CP31: 3346 | CQ31: IND | CR31: IND | CS31: IND | CT31: PTO | CW31: 3346 | CX31: IND | CY31: IND | CZ31: IND | DA31: IND | DD31: IND | DE31: IND | DF31: IND | DG31: PTO | DH31: IND | DK31: IND | DL31: IND | DM31: IND
C32: 3336 | D32: 3336 | E32: 3346 | F32: 3346 | G32: 3328 | J32: 3336 | K32: PTO | L32: 3336 | M32: 3346 | N32: 3328 | Q32: PTO | R32: 3328 | S32: 3328 | T32: 3336 | U32: IND | X32: PTO | Y32: 3328 | Z32: 3328 | AA32: IND | AB32: IND | AE32: PTO | AF32: 3328 | AG32: ASSY | AH32: ASSY | AI32: ASSY | AL32: 3272 | AM32: 3328 | AN32: 3336 | AO32: 3346 | AP32: 3346 | AS32: 3346 | AT32: 3346 | AU32: 3336 | AV32: IND | AW32: IND | AZ32: IND | BA32: IND | BB32: IND | BC32: IND | BD32: IND | BG32: 3346 | BH32: IND | BI32: IND | BJ32: IND | BK32: IND | BN32: 3346 | BO32: 3328 | BP32: IND | BQ32: IND | BR32: PTO | BU32: PTO | BV32: 3346 | BW32: IND | BX32: IND | BY32: IND | CB32: IND | CC32: IND | CD32: IND | CE32: IND | CF32: IND | CI32: 3336 | CJ32: IND | CK32: IND | CL32: PTO | CM32: IND | CP32: IND | CQ32: IND | CR32: IND | CS32: IND | CT32: PTO | CW32: IND | CX32: IND | CY32: IND | CZ32: IND | DA32: IND | DD32: IND | DE32: IND | DF32: IND | DG32: PTO | DH32: IND | DK32: IND | DL32: IND | DM32: IND
C33: 3336 | D33: 3336 | E33: 3346 | F33: 3346 | G33: 3328 | J33: 3336 | K33: PTO | L33: 3336 | M33: IND | N33: 3328 | Q33: PTO | R33: 3328 | S33: 3328 | T33: 3336 | U33: IND | X33: PTO | Y33: 3328 | Z33: 3328 | AA33: IND | AB33: IND | AE33: PTO | AF33: 3328 | AG33: ASSY | AH33: ASSY | AI33: ASSY | AL33: 3272 | AM33: 3328 | AN33: 3346 | AO33: 3346 | AP33: 3346 | AS33: 3346 | AT33: 3346 | AU33: 3336 | AV33: IND | AW33: IND | AZ33: IND | BA33: IND | BB33: IND | BC33: IND | BD33: IND | BG33: 3346 | BH33: IND | BI33: IND | BJ33: IND | BK33: IND | BN33: 3346 | BO33: IND | BP33: IND | BQ33: IND | BR33: PTO | BU33: PTO | BV33: 3346 | BW33: IND | BX33: IND | BY33: IND | CB33: IND | CC33: IND | CD33: IND | CE33: IND | CF33: IND | CI33: 3336 | CJ33: IND | CK33: IND | CL33: PTO | CM33: IND | CP33: IND | CQ33: IND | CR33: IND | CS33: IND | CT33: PTO | CW33: IND | CX33: IND | CY33: IND | CZ33: IND | DA33: IND | DD33: IND | DE33: IND | DF33: IND | DG33: PTO | DH33: IND | DK33: IND | DL33: IND | DM33: IND
C34: 3336 | D34: 3336 | E34: 3346 | F34: 3346 | G34: 3328 | J34: 3336 | K34: PTO | L34: 3336 | M34: IND | N34: 3328 | Q34: PTO | R34: 3328 | S34: 3328 | T34: 3336 | U34: IND | X34: PTO | Y34: 3328 | Z34: 3328 | AA34: IND | AB34: IND | AE34: PTO | AF34: 3328 | AG34: ASSY | AH34: ASSY | AI34: ASSY | AL34: 3272 | AM34: 3328 | AN34: 3346 | AO34: 3346 | AP34: 3346 | AS34: 3346 | AT34: 3346 | AU34: IND | AV34: IND | AW34: IND | AZ34: IND | BA34: IND | BB34: IND | BC34: IND | BD34: IND | BG34: 3346 | BH34: IND | BI34: IND | BJ34: IND | BK34: IND | BN34: 3346 | BO34: IND | BP34: IND | BQ34: IND | BR34: PTO | BU34: PTO | BV34: IND | BW34: IND | BX34: IND | BY34: IND | CB34: IND | CC34: IND | CD34: IND | CE34: IND | CF34: IND | CI34: 3336 | CJ34: IND | CK34: IND | CL34: PTO | CM34: IND | CP34: IND | CQ34: IND | CR34: IND | CS34: IND | CT34: PTO | CW34: IND | CX34: IND | CY34: IND | CZ34: IND | DA34: IND | DD34: IND | DE34: IND | DF34: IND | DG34: PTO | DH34: IND | DK34: IND | DL34: IND | DM34: IND
C35: 3336 | D35: 3336 | E35: 3346 | F35: 3346 | G35: 3328 | J35: 3336 | K35: PTO | L35: 3336 | M35: IND | N35: 3328 | Q35: PTO | R35: 3328 | S35: 3328 | T35: 3336 | U35: IND | X35: PTO | Y35: 3328 | Z35: 3328 | AA35: IND | AB35: IND | AE35: PTO | AF35: 3328 | AG35: ASSY | AH35: ASSY | AI35: ASSY | AL35: 3272 | AM35: 3328 | AN35: 3346 | AO35: 3346 | AP35: IND | AS35: 3346 | AT35: 3346 | AU35: IND | AV35: IND | AW35: IND | AZ35: IND | BA35: IND | BB35: IND | BC35: IND | BD35: IND | BG35: 3346 | BH35: IND | BI35: IND | BJ35: IND | BK35: IND | BN35: 3346 | BO35: IND | BP35: IND | BQ35: IND | BR35: PTO | BU35: PTO | BV35: IND | BW35: IND | BX35: IND | BY35: IND | CB35: IND | CC35: IND | CD35: IND | CE35: IND | CF35: IND | CI35: IND | CJ35: IND | CK35: IND | CL35: PTO | CM35: IND | CP35: IND | CQ35: IND | CR35: IND | CS35: IND | CT35: PTO | CW35: IND | CX35: IND | CY35: IND | CZ35: IND | DA35: IND | DD35: IND | DE35: IND | DF35: IND | DG35: PTO | DH35: IND | DK35: IND | DL35: IND | DM35: IND
C36: 3336 | D36: 3336 | E36: 3272 | F36: 3346 | G36: 3328 | J36: 3336 | K36: PTO | L36: 3336 | M36: 3272 | N36: 3328 | Q36: PTO | R36: 3328 | S36: 3328 | T36: 3336 | U36: IND | X36: PTO | Y36: 3328 | Z36: 3328 | AA36: IND | AB36: IND | AE36: PTO | AF36: 3328 | AG36: ASSY | AH36: ASSY | AI36: ASSY | AL36: 3272 | AM36: 3328 | AN36: 3346 | AO36: 3346 | AP36: IND | AS36: 3346 | AT36: 3346 | AU36: IND | AV36: IND | AW36: IND | AZ36: IND | BA36: IND | BB36: IND | BC36: IND | BD36: IND | BG36: 3346 | BH36: IND | BI36: IND | BJ36: IND | BK36: IND | BN36: 3346 | BO36: IND | BP36: IND | BQ36: IND | BR36: PTO | BU36: PTO | BV36: IND | BW36: IND | BX36: IND | BY36: IND | CB36: IND | CC36: IND | CD36: IND | CE36: IND | CF36: IND | CI36: IND | CJ36: IND | CK36: IND | CL36: PTO | CM36: IND | CP36: IND | CQ36: IND | CR36: IND | CS36: IND | CT36: PTO | CW36: IND | CX36: IND | CY36: IND | CZ36: IND | DA36: IND | DD36: IND | DE36: IND | DF36: IND | DG36: PTO | DH36: IND | DK36: IND | DL36: IND | DM36: IND
B40: José Wenceslao
B52: Adrian C | C52: IND | D52: 3340 | E52: 3340 | F52: 3328 | G52: 3328 | J52: MG | K52: PTO | L52: 3328 | M52: IND | N52: IND | Q52: MNG | R52: 3340 | S52: IND | T52: PTO | U52: PTO | X52: PTO | Y52: PTO | Z52: 3328 | AA52: MNG | AB52: 3340 | AE52: MNG | AF52: MNG | AG52: MNG | AH52: IND | AI52: MNG | AL52: MNG | AM52: MNG | AN52: MNG | AO52: 3341 | AP52: MNG | AS52: MNG | AT52: MNG | AU52: MNG | AV52: 3331 | AW52: 3340 | AZ52: MNG | BA52: MNG | BB52: MNG | BC52: IND | BD52: IND | BG52: MNG | BH52: MNG | BI52: MNG | BJ52: IND | BK52: IND | BN52: MNG | BO52: MNG | BP52: MNG | BQ52: IND | BR52: IND | BU52: PTO | BV52: MNG | BW52: MNG | BX52: IND | BY52: IND | CB52: MNG | CC52: MNG | CD52: MNG | CE52: IND | CF52: IND | CI52: MNG | CJ52: MNG | CK52: MNG | CL52: IND | CM52: 3328 | CP52: MNG | CQ52: MNG | CR52: MNG | CS52: IND | CT52: IND | CW52: MNG | CX52: MNG | CY52: MNG | CZ52: IND | DA52: 3328 | DD52: PTO | DE52: PTO | DF52: PTO | DG52: PTO | DH52: PTO | DK52: PTO | DL52: PTO | DM52: PTO
C53: IND | D53: 3340 | E53: 3340 | F53: 3328 | G53: 3328 | J53: IND | K53: PTO | L53: 3328 | M53: IND | N53: IND | Q53: MNG | R53: IND | S53: IND | T53: PTO | U53: PTO | X53: PTO | Y53: PTO | Z53: 3328 | AA53: MNG | AB53: 3340 | AE53: MNG | AF53: 3331 | AG53: MNG | AH53: IND | AI53: MNG | AL53: MNG | AM53: IND | AN53: MNG | AO53: 3341 | AP53: MNG | AS53: MNG | AT53: 3328 | AU53: MNG | AV53: 3331 | AW53: 3340 | AZ53: MNG | BA53: IND | BB53: MNG | BC53: IND | BD53: IND | BG53: MNG | BH53: IND | BI53: MNG | BJ53: IND | BK53: IND | BN53: MNG | BO53: IND | BP53: MNG | BQ53: IND | BR53: IND | BU53: PTO | BV53: IND | BW53: MNG | BX53: IND | BY53: IND | CB53: MNG | CC53: IND | CD53: MNG | CE53: IND | CF53: IND | CI53: MNG | CJ53: IND | CK53: MNG | CL53: IND | CM53: IND | CP53: MNG | CQ53: IND | CR53: MNG | CS53: IND | CT53: IND | CW53: MNG | CX53: IND | CY53: MNG | CZ53: IND | DA53: 3328 | DD53: PTO | DE53: PTO | DF53: PTO | DG53: PTO | DH53: PTO | DK53: PTO | DL53: PTO | DM53: PTO
C54: IND | D54: 3340 | E54: 3340 | F54: 3328 | G54: 3328 | J54: IND | K54: PTO | L54: 3328 | M54: IND | N54: IND | Q54: MNG | R54: IND | S54: IND | T54: PTO | U54: PTO | X54: PTO | Y54: PTO | Z54: IND | AA54: IND | AB54: 3340 | AE54: IND | AF54: 3331 | AG54: MNG | AH54: IND | AI54: IND | AL54: IND | AM54: IND | AN54: MNG | AO54: 3341 | AP54: 3331 | AS54: IND | AT54: IND | AU54: MNG | AV54: 3331 | AW54: 3340 | AZ54: IND | BA54: IND | BB54: MNG | BC54: IND | BD54: IND | BG54: IND | BH54: IND | BI54: MNG | BJ54: IND | BK54: IND | BN54: IND | BO54: IND | BP54: MNG | BQ54: IND | BR54: IND | BU54: PTO | BV54: IND | BW54: MNG | BX54: IND | BY54: IND | CB54: IND | CC54: IND | CD54: MNG | CE54: IND | CF54: IND | CI54: IND | CJ54: IND | CK54: MNG | CL54: IND | CM54: IND | CP54: IND | CQ54: IND | CR54: MNG | CS54: IND | CT54: IND | CW54: IND | CX54: IND | CY54: MNG | CZ54: IND | DA54: 3346 | DD54: PTO | DE54: PTO | DF54: PTO | DG54: PTO | DH54: PTO | DK54: PTO | DL54: PTO | DM54: PTO
C55: IND | D55: 3340 | E55: 3340 | F55: 3328 | G55: 3328 | J55: IND | K55: PTO | L55: 3328 | M55: IND | N55: IND | Q55: IND | R55: IND | S55: IND | T55: PTO | U55: PTO | X55: PTO | Y55: PTO | Z55: IND | AA55: IND | AB55: 3340 | AE55: IND | AF55: IND | AG55: IND | AH55: IND | AI55: IND | AL55: IND | AM55: IND | AN55: IND | AO55: 3341 | AP55: 3331 | AS55: IND | AT55: IND | AU55: IND | AV55: IND | AW55: 3340 | AZ55: IND | BA55: IND | BB55: IND | BC55: IND | BD55: IND | BG55: IND | BH55: IND | BI55: IND | BJ55: IND | BK55: IND | BN55: IND | BO55: IND | BP55: IND | BQ55: IND | BR55: IND | BU55: PTO | BV55: IND | BW55: IND | BX55: IND | BY55: IND | CB55: IND | CC55: IND | CD55: IND | CE55: IND | CF55: IND | CI55: IND | CJ55: IND | CK55: IND | CL55: IND | CM55: IND | CP55: IND | CQ55: IND | CR55: IND | CS55: IND | CT55: IND | CW55: IND | CX55: IND | CY55: IND | CZ55: IND | DA55: 3346 | DD55: PTO | DE55: PTO | DF55: PTO | DG55: PTO | DH55: PTO | DK55: PTO | DL55: PTO | DM55: PTO
C56: IND | D56: 3340 | E56: 3340 | F56: 3328 | G56: 3328 | J56: IND | K56: PTO | L56: 3328 | M56: IND | N56: IND | Q56: IND | R56: IND | S56: IND | T56: PTO | U56: PTO | X56: PTO | Y56: PTO | Z56: IND | AA56: IND | AB56: 3340 | AE56: IND | AF56: IND | AG56: IND | AH56: IND | AI56: IND | AL56: IND | AM56: IND | AN56: IND | AO56: 3341 | AP56: 3331 | AS56: IND | AT56: IND | AU56: IND | AV56: IND | AW56: 3340 | AZ56: IND | BA56: IND | BB56: IND | BC56: IND | BD56: IND | BG56: IND | BH56: IND | BI56: IND | BJ56: IND | BK56: IND | BN56: IND | BO56: IND | BP56: IND | BQ56: IND | BR56: IND | BU56: PTO | BV56: IND | BW56: IND | BX56: IND | BY56: IND | CB56: IND | CC56: IND | CD56: IND | CE56: IND | CF56: IND | CI56: IND | CJ56: IND | CK56: IND | CL56: PTO | CM56: IND | CP56: IND | CQ56: IND | CR56: IND | CS56: IND | CT56: IND | CW56: IND | CX56: IND | CY56: IND | CZ56: IND | DA56: IND | DD56: PTO | DE56: PTO | DF56: PTO | DG56: PTO | DH56: PTO | DK56: PTO | DL56: PTO | DM56: PTO
C57: IND | D57: 3340 | E57: 3340 | F57: 3328 | G57: 3328 | J57: IND | K57: PTO | L57: 3328 | M57: IND | N57: IND | Q57: IND | R57: IND | S57: IND | T57: PTO | U57: PTO | X57: PTO | Y57: PTO | Z57: IND | AA57: IND | AB57: 3340 | AE57: IND | AF57: IND | AG57: IND | AH57: IND | AI57: IND | AL57: IND | AM57: IND | AN57: IND | AO57: 3341 | AP57: IND | AS57: IND | AT57: IND | AU57: IND | AV57: IND | AW57: 3340 | AZ57: IND | BA57: IND | BB57: IND | BC57: IND | BD57: IND | BG57: IND | BH57: IND | BI57: IND | BJ57: IND | BK57: IND | BN57: IND | BO57: IND | BP57: IND | BQ57: IND | BR57: IND | BU57: PTO | BV57: IND | BW57: IND | BX57: IND | BY57: IND | CB57: IND | CC57: IND | CD57: IND | CE57: IND | CF57: IND | CI57: IND | CJ57: IND | CK57: IND | CL57: PTO | CM57: IND | CP57: IND | CQ57: IND | CR57: IND | CS57: IND | CT57: IND | CW57: IND | CX57: IND | CY57: IND | CZ57: IND | DA57: IND | DD57: PTO | DE57: PTO | DF57: PTO | DG57: PTO | DH57: PTO | DK57: PTO | DL57: PTO | DM57: PTO
...

Sheet HD Forecast 2026
A1: #VALUE! | B1: Month | C1: January | AH1: February | BJ1: March | CO1: April | DS1: May | EX1: June | GB1: July | HG1: August | IL1: September | JP1: October | KU1: November | LY1: December
B2: Week | C2: 1 | G2: 2 | N2: 3 | U2: 4 | AB2: 5 | AI2: 6 | AP2: 7 | AW2: 8 | BD2: 9 | BK2: 10 | BR2: 11 | BY2: 12 | CF2: 13 | CM2: 14 | CT2: 15 | DA2: 16 | DH2: 17 | DO2: 18 | DV2: 19 | EC2: 20 | EJ2: 21 | EQ2: 22 | EX2: 23 | FE2: 24 | FL2: 25 | FS2: 26 | FZ2: 27 | GG2: 28 | GN2: 29 | GU2: 30 | HB2: 31 | HI2: 32 | HP2: 33 | HW2: 34 | ID2: 35 | IK2: 36 | IR2: 37 | IY2: 38 | JF2: 39 | JM2: 40 | JT2: 41 | KA2: 42 | KH2: 43 | KO2: 44 | KV2: 45 | LC2: 46 | LJ2: 47 | LQ2: 48 | LX2: 49 | ME2: 50 | ML2: 51 | MS2: 52 | MZ2: 53
B3: Day | C3: 1 | D3: 2 | E3: 3 | F3: 4 | G3: 5 | H3: 6 | I3: 7 | J3: 8 | K3: 9 | L3: 10 | M3: 11 | N3: 12 | O3: 13 | P3: 14 | Q3: 15 | R3: 16 | S3: 17 | T3: 18 | U3: 19 | V3: 20 | W3: 21 | X3: 22 | Y3: 23 | Z3: 24 | AA3: 25 | AB3: 26 | AC3: 27 | AD3: 28 | AE3: 29 | AF3: 30 | AG3: 31 | AH3: 1 | AI3: 2 | AJ3: 3 | AK3: 4 | AL3: 5 | AM3: 6 | AN3: 7 | AO3: 8 | AP3: 9 | AQ3: 10 | AR3: 11 | AS3: 12 | AT3: 13 | AU3: 14 | AV3: 15 | AW3: 16 | AX3: 17 | AY3: 18 | AZ3: 19 | BA3: 20 | BB3: 21 | BC3: 22 | BD3: 23 | BE3: 24 | BF3: 25 | BG3: 26 | BH3: 27 | BI3: 28 | BJ3: 1 | BK3: 2 | BL3: 3 | BM3: 4 | BN3: 5 | BO3: 6 | BP3: 7 | BQ3: 8 | BR3: 9 | BS3: 10 | BT3: 11 | BU3: 12 | BV3: 13 | BW3: 14 | BX3: 15 | BY3: 16 | BZ3: 17 | CA3: 18 | CB3: 19 | CC3: 20 | CD3: 21 | CE3: 22 | CF3: 23 | CG3: 24 | CH3: 25 | CI3: 26 | CJ3: 27 | CK3: 28 | CL3: 29 | CM3: 30 | CN3: 31 | CO3: 1 | CP3: 2 | CQ3: 3 | CR3: 4 | CS3: 5 | CT3: 6 | CU3: 7 | CV3: 8 | CW3: 9 | CX3: 10 | CY3: 11 | CZ3: 12 | DA3: 13 | DB3: 14 | DC3: 15 | DD3: 16 | DE3: 17 | DF3: 18 | DG3: 19 | DH3: 20 | DI3: 21 | DJ3: 22 | DK3: 23 | DL3: 24 | DM3: 25 | DN3: 26 | DO3: 27 | DP3: 28 | DQ3: 29 | DR3: 30 | DS3: 1 | DT3: 2 | DU3: 3 | DV3: 4 | DW3: 5 | DX3: 6 | DY3: 7 | DZ3: 8 | EA3: 9 | EB3: 10 | EC3: 11 | ED3: 12 | EE3: 13 | EF3: 14 | EG3: 15 | EH3: 16 | EI3: 17 | EJ3: 18 | EK3: 19 | EL3: 20 | EM3: 21 | EN3: 22 | EO3: 23 | EP3: 24 | EQ3: 25 | ER3: 26 | ES3: 27 | ET3: 28 | EU3: 29 | EV3: 30 | EW3: 31 | EX3: 1 | EY3: 2 | EZ3: 3 | FA3: 4 | FB3: 5 | FC3: 6 | FD3: 7 | FE3: 8 | FF3: 9 | FG3: 10 | FH3: 11 | FI3: 12 | FJ3: 13 | FK3: 14 | FL3: 15 | FM3: 16 | FN3: 17 | FO3: 18 | FP3: 19 | FQ3: 20 | FR3: 21 | FS3: 22 | FT3: 23 | FU3: 24 | FV3: 25 | FW3: 26 | FX3: 27 | FY3: 28 | FZ3: 29 | GA3: 30 | GB3: 1 | GC3: 2 | GD3: 3 | GE3: 4 | GF3: 5 | GG3: 6 | GH3: 7 | GI3: 8 | GJ3: 9 | GK3: 10 | GL3: 11 | GM3: 12 | GN3: 13 | GO3: 14 | GP3: 15 | GQ3: 16 | GR3: 17 | GS3: 18 | GT3: 19 | GU3: 20 | GV3: 21 | GW3: 22 | GX3: 23 | GY3: 24 | GZ3: 25 | HA3: 26 | HB3: 27 | HC3: 28 | HD3: 29 | HE3: 30 | HF3: 31 | HG3: 1 | HH3: 2 | HI3: 3 | HJ3: 4 | HK3: 5 | HL3: 6 | HM3: 7 | HN3: 8 | HO3: 9 | HP3: 10 | HQ3: 11 | HR3: 12 | HS3: 13 | HT3: 14 | HU3: 15 | HV3: 16 | HW3: 17 | HX3: 18 | HY3: 19 | HZ3: 20 | IA3: 21 | IB3: 22 | IC3: 23 | ID3: 24 | IE3: 25 | IF3: 26 | IG3: 27 | IH3: 28 | II3: 29 | IJ3: 30 | IK3: 31 | IL3: 1 | IM3: 2 | IN3: 3 | IO3: 4 | IP3: 5 | IQ3: 6 | IR3: 7 | IS3: 8 | IT3: 9 | IU3: 10 | IV3: 11 | IW3: 12 | IX3: 13 | IY3: 14 | IZ3: 15 | JA3: 16 | JB3: 17 | JC3: 18 | JD3: 19 | JE3: 20 | JF3: 21 | JG3: 22 | JH3: 23 | JI3: 24 | JJ3: 25 | JK3: 26 | JL3: 27 | JM3: 28 | JN3: 29 | JO3: 30 | JP3: 1 | JQ3: 2 | JR3: 3 | JS3: 4 | JT3: 5 | JU3: 6 | JV3: 7 | JW3: 8 | JX3: 9 | JY3: 10 | JZ3: 11 | KA3: 12 | KB3: 13 | KC3: 14 | KD3: 15 | KE3: 16 | KF3: 17 | KG3: 18 | KH3: 19 | KI3: 20 | KJ3: 21 | KK3: 22 | KL3: 23 | KM3: 24 | KN3: 25 | KO3: 26 | KP3: 27 | KQ3: 28 | KR3: 29 | KS3: 30 | KT3: 31 | KU3: 1 | KV3: 2 | KW3: 3 | KX3: 4 | KY3: 5 | KZ3: 6 | LA3: 7 | LB3: 8 | LC3: 9 | LD3: 10 | LE3: 11 | LF3: 12 | LG3: 13 | LH3: 14 | LI3: 15 | LJ3: 16 | LK3: 17 | LL3: 18 | LM3: 19 | LN3: 20 | LO3: 21 | LP3: 22 | LQ3: 23 | LR3: 24 | LS3: 25 | LT3: 26 | LU3: 27 | LV3: 28 | LW3: 29 | LX3: 30 | LY3: 1 | LZ3: 2 | MA3: 3 | MB3: 4 | MC3: 5 | MD3: 6 | ME3: 7 | MF3: 8 | MG3: 9 | MH3: 10 | MI3: 11 | MJ3: 12 | MK3: 13 | ML3: 14 | MM3: 15 | MN3: 16 | MO3: 17 | MP3: 18 | MQ3: 19 | MR3: 20 | MS3: 21 | MT3: 22 | MU3: 23 | MV3: 24 | MW3: 25 | MX3: 26 | MY3: 27 | MZ3: 28 | NA3: 29 | NB3: 30 | NC3: 31
A4: IND | B4: Juan Adame | C4: PTO | D4: IND | N4: 3272 | O4: 3363 | P4: IND | Q4: IND | R4: IND | U4: 3300 | V4: 3300 | W4: 3363 | X4: 3363 | Y4: IND | AB4: 3300 | AC4: 3300 | AD4: 3363 | AE4: 3363 | AF4: 3336 | AI4: HOL | AJ4: IND | AK4: IND | AL4: IND | AM4: IND | AP4: 3300 | AQ4: 3300 | AR4: 3363 | AS4: 3363 | AT4: IND | AW4: 3300 | AX4: 3300 | AY4: 3300 | AZ4: 3363 | BA4: IND | BD4: 3300 | BE4: 3300 | BF4: IND | BG4: IND | BH4: IND | BK4: 3300 | BL4: 3300 | BM4: 3300 | BN4: IND | BO4: IND
A5: MNG | C5: PTO | D5: IND | N5: 3336 | O5: 3363 | P5: IND | Q5: IND | R5: IND | U5: 3300 | V5: 3300 | W5: 3363 | X5: 3363 | Y5: IND | AB5: 3300 | AC5: 3300 | AD5: 3363 | AE5: 3363 | AF5: 3336 | AI5: HOL | AJ5: IND | AK5: IND | AL5: IND | AM5: IND | AP5: 3300 | AQ5: 3300 | AR5: 3363 | AS5: 3363 | AT5: IND | AW5: 3300 | AX5: 3300 | AY5: 3300 | AZ5: 3363 | BA5: IND | BD5: 3300 | BE5: 3300 | BF5: IND | BG5: IND | BH5: IND | BK5: 3300 | BL5: 3300 | BM5: 3300 | BN5: IND | BO5: IND
A6: ASSY | C6: PTO | D6: IND | N6: 3336 | O6: 3363 | P6: IND | Q6: IND | R6: IND | U6: 3300 | V6: 3300 | W6: 3363 | X6: 3363 | Y6: IND | AB6: 3300 | AC6: 3300 | AD6: 3363 | AE6: 3363 | AF6: 3336 | AI6: HOL | AJ6: IND | AK6: IND | AL6: IND | AM6: IND | AP6: 3300 | AQ6: 3300 | AR6: 3363 | AS6: 3363 | AT6: IND | AW6: 3300 | AX6: 3300 | AY6: 3300 | AZ6: IND | BA6: IND | BD6: 3300 | BE6: 3300 | BF6: IND | BG6: IND | BH6: IND | BK6: 3300 | BL6: 3300 | BM6: 3300 | BN6: IND | BO6: IND
A7: PTO | C7: PTO | D7: IND | N7: 3363 | O7: 3363 | P7: IND | Q7: IND | R7: IND | U7: 3300 | V7: 3300 | W7: 3363 | X7: 3272 | Y7: IND | AB7: 3300 | AC7: 3300 | AD7: 3363 | AE7: 3363 | AF7: 3336 | AI7: HOL | AJ7: IND | AK7: IND | AL7: IND | AM7: IND | AP7: 3300 | AQ7: 3300 | AR7: 3363 | AS7: 3363 | AT7: IND | AW7: 3300 | AX7: 3300 | AY7: 3300 | AZ7: IND | BA7: IND | BD7: 3300 | BE7: 3300 | BF7: IND | BG7: IND | BH7: IND | BK7: 3300 | BL7: 3300 | BM7: 3300 | BN7: IND | BO7: IND
A8: 3268 | C8: PTO | D8: IND | N8: 3363 | O8: 3363 | P8: IND | Q8: IND | R8: IND | U8: 3300 | V8: 3300 | W8: 3363 | X8: IND | Y8: IND | AB8: 3300 | AC8: 3300 | AD8: 3363 | AE8: 3363 | AF8: 3336 | AI8: HOL | AJ8: IND | AK8: IND | AL8: IND | AM8: IND | AP8: 3300 | AQ8: 3300 | AR8: 3363 | AS8: 3363 | AT8: IND | AW8: 3300 | AX8: 3300 | AY8: 3300 | AZ8: IND | BA8: IND | BD8: 3300 | BE8: 3300 | BF8: IND | BG8: IND | BH8: IND | BK8: 3300 | BL8: 3300 | BM8: 3300 | BN8: IND | BO8: IND
A9: 3335 | C9: PTO | D9: IND | N9: 3363 | O9: 3363 | P9: IND | Q9: IND | R9: IND | U9: 3300 | V9: 3300 | W9: 3363 | X9: IND | Y9: IND | AB9: 3300 | AC9: 3300 | AD9: 3363 | AE9: 3363 | AF9: 3336 | AI9: HOL | AJ9: IND | AK9: IND | AL9: IND | AM9: IND | AP9: 3300 | AQ9: 3300 | AR9: 3363 | AS9: 3363 | AT9: IND | AW9: 3300 | AX9: 3300 | AY9: 3300 | AZ9: IND | BA9: IND | BD9: 3300 | BE9: 3300 | BF9: IND | BG9: IND | BH9: IND | BK9: 3300 | BL9: 3300 | BM9: 3300 | BN9: IND | BO9: IND
A10: 3332 | C10: PTO | D10: IND | N10: 3363 | O10: 3363 | P10: IND | Q10: IND | R10: IND | U10: 3300 | V10: 3363 | W10: 3363 | X10: IND | Y10: IND | AB10: 3300 | AC10: 3300 | AD10: 3363 | AE10: 3336 | AF10: 3336 | AI10: HOL | AJ10: IND | AK10: IND | AL10: IND | AM10: IND | AP10: 3300 | AQ10: 3300 | AR10: 3363 | AS10: IND | AT10: IND | AW10: 3300 | AX10: 3300 | AY10: 3300 | AZ10: IND | BA10: IND | BD10: 3300 | BE10: 3300 | BF10: IND | BG10: IND | BH10: IND | BK10: 3300 | BL10: 3300 | BM10: 3300 | BN10: IND | BO10: IND
A11: 3328 | C11: PTO | D11: IND | N11: 3363 | O11: 3363 | P11: IND | Q11: IND | R11: IND | U11: 3300 | V11: 3363 | W11: 3363 | X11: IND | Y11: IND | AB11: 3300 | AC11: 3300 | AD11: 3363 | AE11: 3336 | AF11: 3336 | AI11: HOL | AJ11: IND | AK11: IND | AL11: IND | AM11: IND | AP11: 3300 | AQ11: 3300 | AR11: 3363 | AS11: IND | AT11: IND | AW11: 3300 | AX11: 3300 | AY11: 3300 | AZ11: IND | BA11: IND | BD11: 3300 | BE11: 3300 | BF11: IND | BG11: IND | BH11: IND | BK11: 3300 | BL11: 3300 | BM11: 3300 | BN11: IND | BO11: IND
A12: 3346 | C12: PTO | D12: IND | N12: 3363 | O12: 3363 | P12: IND | Q12: IND | R12: IND | U12: 3300 | V12: 3363 | W12: 3363 | X12: IND | Y12: IND | AB12: 3300 | AC12: 3300 | AD12: 3363 | AE12: 3336 | AF12: 3272 | AI12: HOL | AJ12: IND | AK12: IND | AL12: IND | AM12: IND | AP12: 3300 | AQ12: 3300 | AR12: 3363 | AS12: IND | AT12: 3272 | AW12: 3300 | AX12: 3300 | AY12: 3300 | AZ12: IND | BA12: IND | BD12: 3300 | BE12: 3300 | BF12: IND | BG12: IND | BH12: IND | BK12: 3300 | BL12: 3300 | BM12: 3300 | BN12: IND | BO12: IND
A13: 3334
A14: 3336
A15: 3272
A16: 3363 | B16: Fidel Maldonado | C16: PTO | D16: PTO | G16: IND | H16: 3332 | I16: 3332 | J16: 3332 | K16: 3332 | N16: 3334 | O16: 3332 | P16: 3332 | Q16: 3332 | R16: 3332 | U16: 3297 | V16: 3335 | W16: IND | X16: IND | Y16: IND | AB16: 3297 | AC16: 3297 | AD16: IND | AE16: IND | AF16: IND | AI16: HOL | AJ16: 3297 | AK16: 3332 | AL16: 3332 | AM16: 3332 | AP16: 3332 | AQ16: 3332 | AR16: 3332 | AS16: 3332 | AT16: IND | AW16: 3297 | AX16: 3297 | AY16: 3297 | AZ16: 3332 | BA16: 3332 | BD16: IND | BE16: IND | BF16: IND | BG16: IND | BH16: IND | BK16: 3332 | BL16: 3332 | BM16: 3332 | BN16: 3332 | BO16: IND
A17: 3300 | C17: PTO | D17: PTO | G17: IND | H17: 3332 | I17: 3332 | J17: 3332 | K17: 3332 | N17: 3335 | O17: 3332 | P17: 3332 | Q17: 3332 | R17: 3332 | U17: 3297 | V17: IND | W17: IND | X17: IND | Y17: IND | AB17: 3297 | AC17: 3297 | AD17: IND | AE17: IND | AF17: IND | AI17: HOL | AJ17: 3297 | AK17: 3332 | AL17: 3332 | AM17: 3332 | AP17: 3332 | AQ17: 3332 | AR17: 3332 | AS17: IND | AT17: IND | AW17: 3297 | AX17: 3297 | AY17: 3297 | AZ17: 3332 | BA17: 3332 | BD17: IND | BE17: IND | BF17: IND | BG17: IND | BH17: IND | BK17: 3332 | BL17: 3332 | BM17: 3332 | BN17: 3332 | BO17: IND
A18: 3364 | C18: PTO | D18: PTO | G18: IND | H18: 3332 | I18: 3332 | J18: 3332 | K18: 3332 | N18: 3332 | O18: 3332 | P18: 3332 | Q18: 3332 | R18: 3332 | U18: 3297 | V18: IND | W18: IND | X18: IND | Y18: IND | AB18: 3297 | AC18: 3297 | AD18: IND | AE18: IND | AF18: IND | AI18: HOL | AJ18: 3297 | AK18: 3332 | AL18: 3332 | AM18: 3332 | AP18: 3332 | AQ18: 3332 | AR18: 3332 | AS18: IND | AT18: IND | AW18: 3297 | AX18: 3297 | AY18: 3297 | AZ18: 3332 | BA18: 3332 | BD18: IND | BE18: IND | BF18: IND | BG18: IND | BH18: IND | BK18: 3332 | BL18: 3332 | BM18: 3332 | BN18: 3332 | BO18: IND
A19: 3341 | C19: PTO | D19: PTO | G19: IND | H19: IND | I19: IND | J19: IND | K19: IND | N19: 3332 | O19: 3332 | P19: 3332 | Q19: 3332 | R19: 3332 | U19: 3297 | V19: IND | W19: IND | X19: IND | Y19: IND | AB19: IND | AC19: IND | AD19: IND | AE19: IND | AF19: IND | AI19: HOL | AJ19: 3297 | AK19: 3332 | AL19: 3332 | AM19: 3332 | AP19: 3332 | AQ19: 3332 | AR19: 3332 | AS19: IND | AT19: IND | AW19: 3297 | AX19: 3297 | AY19: 3297 | AZ19: 3332 | BA19: 3332 | BD19: IND | BE19: IND | BF19: IND | BG19: IND | BH19: IND | BK19: 3332 | BL19: 3332 | BM19: 3332 | BN19: 3332 | BO19: IND
A20: 3351 | C20: PTO | D20: PTO | G20: IND | H20: IND | I20: IND | J20: IND | K20: IND | N20: 3332 | O20: 3332 | P20: 3332 | Q20: 3332 | R20: 3332 | U20: 3297 | V20: IND | W20: IND | X20: IND | Y20: IND | AB20: IND | AC20: IND | AD20: IND | AE20: IND | AF20: IND | AI20: HOL | AJ20: 3297 | AK20: 3332 | AL20: 3332 | AM20: 3332 | AP20: 3332 | AQ20: 3332 | AR20: 3332 | AS20: IND | AT20: IND | AW20: 3297 | AX20: 3297 | AY20: 3297 | AZ20: 3332 | BA20: 3332 | BD20: IND | BE20: IND | BF20: IND | BG20: IND | BH20: IND | BK20: 3332 | BL20: 3332 | BM20: 3332 | BN20: 3332 | BO20: IND
A21: 3321 | C21: PTO | D21: PTO | G21: IND | H21: IND | I21: IND | J21: IND | K21: IND | N21: 3332 | O21: 3332 | P21: 3332 | Q21: 3332 | R21: 3332 | U21: 3297 | V21: IND | W21: IND | X21: IND | Y21: IND | AB21: IND | AC21: IND | AD21: IND | AE21: IND | AF21: IND | AI21: HOL | AJ21: 3297 | AK21: 3332 | AL21: 3332 | AM21: 3332 | AP21: 3332 | AQ21: 3332 | AR21: 3332 | AS21: IND | AT21: IND | AW21: 3297 | AX21: 3297 | AY21: 3297 | AZ21: 3332 | BA21: 3332 | BD21: IND | BE21: IND | BF21: IND | BG21: IND | BH21: IND | BK21: 3332 | BL21: 3332 | BM21: 3332 | BN21: IND | BO21: IND
A22: 3297 | C22: PTO | D22: PTO | G22: IND | H22: IND | I22: IND | J22: IND | K22: IND | N22: 3332 | O22: 3332 | P22: 3332 | Q22: 3332 | R22: 3332 | U22: 3297 | V22: IND | W22: IND | X22: IND | Y22: IND | AB22: IND | AC22: IND | AD22: IND | AE22: IND | AF22: IND | AI22: HOL | AJ22: 3297 | AK22: 3332 | AL22: 3332 | AM22: 3332 | AP22: 3332 | AQ22: 3332 | AR22: 3332 | AS22: IND | AT22: IND | AW22: 3297 | AX22: 3297 | AY22: 3297 | AZ22: 3332 | BA22: 3332 | BD22: IND | BE22: IND | BF22: IND | BG22: IND | BH22: IND | BK22: 3332 | BL22: 3332 | BM22: 3332 | BN22: IND | BO22: IND
A23: 3365 | C23: PTO | D23: PTO | G23: IND | H23: IND | I23: IND | J23: IND | K23: IND | N23: 3332 | O23: 3332 | P23: 3332 | Q23: 3332 | R23: 3332 | U23: 3297 | V23: IND | W23: IND | X23: IND | Y23: IND | AB23: IND | AC23: IND | AD23: IND | AE23: IND | AF23: IND | AI23: HOL | AJ23: 3297 | AK23: 3332 | AL23: 3332 | AM23: 3332 | AP23: 3332 | AQ23: 3332 | AR23: 3332 | AS23: IND | AT23: IND | AW23: 3297 | AX23: 3297 | AY23: 3332 | AZ23: 3332 | BA23: 3332 | BD23: IND | BE23: IND | BF23: IND | BG23: IND | BH23: IND | BK23: 3332 | BL23: 3332 | BM23: 3332 | BN23: IND | BO23: IND
C24: PTO | D24: PTO | G24: IND | H24: IND | I24: IND | J24: IND | K24: IND | N24: 3332 | O24: 3332 | P24: 3332 | Q24: 3332 | R24: 3332 | U24: 3297 | V24: IND | W24: IND | X24: IND | Y24: IND | AB24: IND | AC24: IND | AD24: IND | AE24: IND | AF24: IND | AI24: HOL | AJ24: 3332 | AK24: 3332 | AL24: 3332 | AM24: 3332 | AP24: 3332 | AQ24: 3332 | AR24: 3332 | AS24: IND | AT24: IND | AW24: 3297 | AX24: 3297 | AY24: 3332 | AZ24: 3332 | BA24: 3332 | BD24: IND | BE24: IND | BF24: IND | BG24: IND | BH24: IND | BK24: 3332 | BL24: 3332 | BM24: 3332 | BN24: IND | BO24: IND
B28: Hilda Mata | C28: PTO | D28: PTO | G28: IND | H28: IND | I28: IND | J28: IND | K28: IND | N28: 3328 | O28: 3363 | P28: IND | Q28: IND | R28: IND | U28: 3328 | V28: 3363 | W28: IND | X28: IND | Y28: IND | AB28: 3328 | AC28: 3336 | AD28: 3363 | AE28: 3363 | AF28: IND | AI28: HOL | AJ28: 3346 | AK28: IND | AL28: IND | AM28: IND | AP28: 3346 | AQ28: 3363 | AR28: IND | AS28: IND | AT28: IND | AW28: 3346 | AX28: IND | AY28: IND | AZ28: IND | BA28: IND | BD28: 3346 | BE28: 3365 | BF28: 3365 | BG28: 3365 | BH28: IND | BK28: 3346 | BL28: 3365 | BM28: 3272 | BN28: IND | BO28: IND
C29: PTO | D29: PTO | G29: IND | H29: IND | I29: IND | J29: IND | K29: IND | N29: 3336 | O29: 3363 | P29: IND | Q29: IND | R29: IND | U29: 3346 | V29: 3363 | W29: IND | X29: IND | Y29: IND | AB29: 3346 | AC29: 3336 | AD29: 3363 | AE29: 3363 | AF29: IND | AI29: HOL | AJ29: 3364 | AK29: IND | AL29: IND | AM29: IND | AP29: 3363 | AQ29: 3363 | AR29: IND | AS29: IND | AT29: IND | AW29: 3346 | AX29: IND | AY29: IND | AZ29: IND | BA29: IND | BD29: 3365 | BE29: 3365 | BF29: 3365 | BG29: IND | BH29: IND | BK29: 3346 | BL29: 3272 | BM29: 3272 | BN29: IND | BO29: IND
C30: PTO | D30: PTO | G30: IND | H30: IND | I30: IND | J30: IND | K30: IND | N30: 3336 | O30: 3363 | P30: IND | Q30: IND | R30: IND | U30: 3363 | V30: 3363 | W30: IND | X30: IND | Y30: IND | AB30: 3336 | AC30: 3336 | AD30: 3363 | AE30: 3363 | AF30: IND | AI30: HOL | AJ30: IND | AK30: IND | AL30: IND | AM30: IND | AP30: 3363 | AQ30: 3363 | AR30: IND | AS30: IND | AT30: IND | AW30: 3346 | AX30: IND | AY30: IND | AZ30: IND | BA30: IND | BD30: 3365 | BE30: 3365 | BF30: 3365 | BG30: IND | BH30: IND | BK30: 3346 | BL30: 3272 | BM30: 3272 | BN30: IND | BO30: IND
C31: PTO | D31: PTO | G31: IND | H31: IND | I31: IND | J31: IND | K31: IND | N31: 3346 | O31: 3363 | P31: IND | Q31: IND | R31: IND | U31: 3363 | V31: 3363 | W31: IND | X31: IND | Y31: IND | AB31: 3336 | AC31: 3336 | AD31: 3363 | AE31: 3363 | AF31: IND | AI31: HOL | AJ31: IND | AK31: IND | AL31: IND | AM31: IND | AP31: 3363 | AQ31: 3363 | AR31: IND | AS31: IND | AT31: IND | AW31: 3363 | AX31: IND | AY31: IND | AZ31: IND | BA31: IND | BD31: 3365 | BE31: 3365 | BF31: 3365 | BG31: IND | BH31: IND | BK31: 3365 | BL31: 3272 | BM31: 3272 | BN31: IND | BO31: IND
C32: PTO | D32: PTO | G32: IND | H32: IND | I32: IND | J32: IND | K32: IND | N32: 3363 | O32: 3363 | P32: IND | Q32: IND | R32: IND | U32: 3363 | V32: 3363 | W32: IND | X32: IND | Y32: IND | AB32: 3336 | AC32: 3336 | AD32: 3363 | AE32: 3363 | AF32: IND | AI32: HOL | AJ32: IND | AK32: IND | AL32: IND | AM32: IND | AP32: 3363 | AQ32: 3363 | AR32: IND | AS32: IND | AT32: IND | AW32: 3363 | AX32: IND | AY32: IND | AZ32: IND | BA32: IND | BD32: 3365 | BE32: 3365 | BF32: 3365 | BG32: IND | BH32: IND | BK32: 3365 | BL32: 3272 | BM32: 3272 | BN32: IND | BO32: IND
C33: PTO | D33: PTO | G33: IND | H33: IND | I33: IND | J33: IND | K33: IND | N33: 3363 | O33: 3363 | P33: IND | Q33: IND | R33: IND | U33: 3363 | V33: 3363 | W33: IND | X33: IND | Y33: IND | AB33: 3336 | AC33: 3336 | AD33: 3363 | AE33: 3363 | AF33: IND | AI33: HOL | AJ33: IND | AK33: IND | AL33: IND | AM33: IND | AP33: 3363 | AQ33: 3363 | AR33: IND | AS33: IND | AT33: IND | AW33: IND | AX33: IND | AY33: IND | AZ33: IND | BA33: IND | BD33: 3365 | BE33: 3365 | BF33: 3365 | BG33: IND | BH33: IND | BK33: 3365 | BL33: 3272 | BM33: 3272 | BN33: IND | BO33: IND
C34: PTO | D34: PTO | G34: IND | H34: IND | I34: IND | J34: IND | K34: IND | N34: 3363 | O34: 3363 | P34: IND | Q34: IND | R34: IND | U34: 3363 | V34: 3363 | W34: IND | X34: IND | Y34: IND | AB34: 3336 | AC34: 3336 | AD34: 3363 | AE34: IND | AF34: IND | AI34: HOL | AJ34: IND | AK34: IND | AL34: IND | AM34: IND | AP34: 3363 | AQ34: 3363 | AR34: IND | AS34: IND | AT34: IND | AW34: IND | AX34: IND | AY34: IND | AZ34: IND | BA34: IND | BD34: 3365 | BE34: 3365 | BF34: 3365 | BG34: IND | BH34: IND | BK34: 3365 | BL34: 3272 | BM34: 3272 | BN34: IND | BO34: IND
C35: PTO | D35: PTO | G35: IND | H35: IND | I35: IND | J35: IND | K35: IND | N35: 3363 | O35: 3363 | P35: IND | Q35: IND | R35: IND | U35: 3363 | V35: 3363 | W35: IND | X35: IND | Y35: IND | AB35: 3336 | AC35: 3336 | AD35: 3363 | AE35: IND | AF35: IND | AI35: HOL | AJ35: IND | AK35: IND | AL35: IND | AM35: IND | AP35: 3363 | AQ35: IND | AR35: IND | AS35: IND | AT35: IND | AW35: IND | AX35: IND | AY35: IND | AZ35: IND | BA35: IND | BD35: 3365 | BE35: 3365 | BF35: 3365 | BG35: IND | BH35: IND | BK35: 3365 | BL35: 3272 | BM35: 3272 | BN35: IND | BO35: IND
C36: PTO | D36: PTO | G36: IND | H36: IND | I36: IND | J36: IND | K36: IND | N36: 3363 | O36: 3363 | P36: IND | Q36: IND | R36: IND | U36: 3363 | V36: IND | W36: IND | X36: IND | Y36: IND | AB36: 3336 | AC36: 3336 | AD36: 3363 | AE36: IND | AF36: IND | AI36: HOL | AJ36: IND | AK36: IND | AL36: IND | AM36: IND | AP36: 3363 | AQ36: IND | AR36: IND | AS36: IND | AT36: IND | AW36: IND | AX36: IND | AY36: IND | AZ36: IND | BA36: IND | BD36: 3365 | BE36: 3365 | BF36: 3365 | BG36: IND | BH36: IND | BK36: 3365 | BL36: 3272 | BM36: 3272 | BN36: IND | BO36: IND
B40: Adrian C | C40: PTO | D40: PTO | N40: PTO | O40: PTO | P40: PTO | Q40: MNG | R40: MNG | U40: MNG | V40: MNG | W40: MNG | X40: MNG | Y40: MNG | AB40: 3364 | AC40: 3364 | AD40: 3364 | AE40: 3297 | AF40: MNG | AI40: HOL | AJ40: 3364 | AK40: 3364 | AL40: 3364 | AM40: 3297 | AP40: IND | AQ40: IND | AR40: IND | AS40: IND | AT40: IND | AW40: IND | AX40: IND | AY40: IND | AZ40: IND | BA40: IND | BD40: IND | BE40: IND | BF40: IND | BG40: 3297 | BH40: 3332 | BK40: IND | BL40: IND | BM40: IND | BN40: IND | BO40: IND
C41: PTO | D41: PTO | N41: PTO | O41: PTO | P41: PTO | Q41: MNG | R41: MNG | U41: MNG | V41: MNG | W41: MNG | X41: MNG | Y41: MNG | AB41: 3364 | AC41: 3364 | AD41: 3364 | AE41: 3297 | AF41: MNG | AI41: HOL | AJ41: 3364 | AK41: 3364 | AL41: 3364 | AM41: 3297 | AP41: IND | AQ41: IND | AR41: IND | AS41: IND | AT41: IND | AW41: IND | AX41: IND | AY41: IND | AZ41: IND | BA41: IND | BD41: IND | BE41: IND | BF41: IND | BG41: 3297 | BH41: 3332 | BK41: IND | BL41: IND | BM41: IND | BN41: IND | BO41: IND
C42: PTO | D42: PTO | N42: PTO | O42: PTO | P42: PTO | Q42: 3364 | R42: 3364 | U42: MNG | V42: MNG | W42: MNG | X42: MNG | Y42: MNG | AB42: 3364 | AC42: 3364 | AD42: 3364 | AE42: IND | AF42: IND | AI42: HOL | AJ42: 3364 | AK42: 3364 | AL42: 3364 | AM42: 3364 | AP42: IND | AQ42: IND | AR42: IND | AS42: IND | AT42: IND | AW42: IND | AX42: IND | AY42: IND | AZ42: IND | BA42: IND | BD42: IND | BE42: IND | BF42: IND | BG42: IND | BH42: IND | BK42: IND | BL42: IND | BM42: IND | BN42: IND | BO42: IND
C43: PTO | D43: PTO | N43: PTO | O43: PTO | P43: PTO | Q43: 3364 | R43: 3364 | U43: 3364 | V43: 3364 | W43: 3364 | X43: IND | Y43: IND | AB43: 3364 | AC43: 3364 | AD43: 3364 | AE43: IND | AF43: IND | AI43: HOL | AJ43: 3364 | AK43: 3364 | AL43: 3364 | AM43: 3364 | AP43: IND | AQ43: IND | AR43: IND | AS43: IND | AT43: IND | AW43: IND | AX43: IND | AY43: IND | AZ43: IND | BA43: IND | BD43: IND | BE43: IND | BF43: IND | BG43: IND | BH43: IND | BK43: IND | BL43: IND | BM43: IND | BN43: IND | BO43: IND
C44: PTO | D44: PTO | N44: PTO | O44: PTO | P44: PTO | Q44: 3364 | R44: 3364 | U44: 3364 | V44: 3364 | W44: 3364 | X44: IND | Y44: IND | AB44: 3364 | AC44: 3364 | AD44: 3364 | AE44: IND | AF44: IND | AI44: HOL | AJ44: 3364 | AK44: 3364 | AL44: 3364 | AM44: 3364 | AP44: IND | AQ44: IND | AR44: IND | AS44: IND | AT44: IND | AW44: IND | AX44: IND | AY44: IND | AZ44: IND | BA44: IND | BD44: IND | BE44: IND | BF44: IND | BG44: IND | BH44: IND | BK44: IND | BL44: IND | BM44: IND | BN44: IND | BO44: IND
C45: PTO | D45: PTO | N45: PTO | O45: PTO | P45: PTO | Q45: 3364 | R45: 3364 | U45: 3364 | V45: 3364 | W45: 3364 | X45: IND | Y45: IND | AB45: 3364 | AC45: 3364 | AD45: 3364 | AE45: IND | AF45: IND | AI45: HOL | AJ45: 3364 | AK45: 3364 | AL45: 3364 | AM45: IND | AP45: IND | AQ45: IND | AR45: IND | AS45: IND | AT45: IND | AW45: IND | AX45: IND | AY45: IND | AZ45: IND | BA45: IND | BD45: IND | BE45: IND | BF45: IND | BG45: IND | BH45: IND | BK45: IND | BL45: IND | BM45: IND | BN45: IND | BO45: IND
C46: PTO | D46: PTO | N46: PTO | O46: PTO | P46: PTO | Q46: 3364 | R46: 3364 | U46: 3364 | V46: 3364 | W46: 3364 | X46: IND | Y46: IND | AB46: 3364 | AC46: 3364 | AD46: 3364 | AE46: IND | AF46: IND | AI46: HOL | AJ46: 3364 | AK46: 3364 | AL46: 3364 | AM46: IND | AP46: IND | AQ46: IND | AR46: IND | AS46: IND | AT46: IND | AW46: IND | AX46: IND | AY46: IND | AZ46: IND | BA46: IND | BD46: IND | BE46: IND | BF46: IND | BG46: IND | BH46: IND | BK46: IND | BL46: IND | BM46: IND | BN46: IND | BO46: IND
...

Sheet Database
